Workbook

Sheet Leads
A1: Priority | B1: Company | C1: Segment | D1: Sub-type | E1: Country | F1: City | G1: Email | H1: Email type | I1: Phone | J1: Website | K1: LinkedIn | L1: What they do | M1: Why they fit | N1: Pitch angle | O1: Demo link path (add to your demo URL) | P1: Email source | Q1: Status | R1: Date sent | S1: Notes
A2: A | B2: Dutum Company Limited | C2: Facility management | D2: Integrated FM | E2: Nigeria | F2: Lagos | G2: info@dutumgroup.com | H2: Company inbox | J2: https://dutumgroup.com/ | L2: Construction and facility management firm offering building FM across Nigeria. | M2: Core fit: recurring field maintenance across many sites. Multi-location. | N2: Multi-building portfolio: planned maintenance schedules, technician dispatch and per-building client reporting. | O2: /demo?industry=facilities&client=Dutum%20Company%20Limited | P2: https://dutumgroup.com/contact/ | Q2: Not contacted
A3: A | B3: Elektrint (Nigeria) Limited | C3: Facility management | D3: MEP maintenance | E3: Nigeria | F3: Lagos | G3: elektrintlagos@elektrint.com | H3: Company inbox | I3: +234 9 782 2768 | J3: https://www.elektrint.com/ | K3: https://www.linkedin.com/company/elektrint-nigeria-ltd./ | L3: Electromechanical installation and facility maintenance services, with branches in Lagos, Abuja and Port Harcourt. | M3: Good fit: maintenance work across client sites. Multi-location. | N3: Maintenance contracts across client buildings: work orders, checklists and proof of work per visit. | O3: /demo?industry=facilities&client=Elektrint | P3: https://www.elektrint.com/ | Q3: Not contacted
A4: A | B4: Global Property & Facilities International Ltd (GPFI) | C4: Facility management | D4: Integrated FM | E4: Nigeria | F4: Lagos | G4: bd@globalpfi.com | H4: Company inbox | I4: +234 803 332 7649 | J4: https://gpfi.ng/ | K4: https://www.linkedin.com/company/gpfinigeria | L4: Integrated FM, security and sustainability technology for commercial, residential, healthcare and industrial sites, operating in several African countries. | M4: Core fit: recurring field maintenance across many sites. Multi-location. | N4: Multi-building portfolio: planned maintenance schedules, technician dispatch and per-building client reporting. | O4: /demo?industry=facilities&client=Global%20Property%20%26%20Facilities%20International%20Ltd | P4: https://gpfi.ng/ | Q4: Not contacted
A5: A | B5: Jide Taiwo & Co. | C5: Facility management | D5: Property / estate FM | E5: Nigeria | F5: Lagos | G5: info@jidetaiwoandco.com | H5: Company inbox | J5: https://jidetaiwoandco.com/ | L5: Estate surveying firm with a nationwide facility and property management division for residential, commercial and retail buildings. | M5: Good fit: maintenance work across client sites. Multi-location. | N5: Tenant requests become tracked work orders with technician dispatch and landlord reporting. | O5: /demo?industry=facilities&client=Jide%20Taiwo%20%26%20Co. | P5: https://jidetaiwoandco.com/contact.php | Q5: Not contacted
A6: A | B6: Kleenol Nigeria Limited | C6: Facility management | D6: HVAC maintenance | E6: Nigeria | F6: Lagos | G6: kleenol@yahoo.co.uk | H6: Free-mail inbox | I6: +234 803 506 6601 | J6: https://www.kleenolng.com/ | K6: https://www.linkedin.com/company/kleenol-nigeria-professional-cleaning-services-company/ | L6: FM covering electrical, plumbing, HVAC and generator maintenance (2.5 kVA to 2,500 kVA) as well as cleaning; offices in Lagos and Abuja. | M6: Good fit: maintenance work across client sites. Multi-location. | N6: Annual maintenance contracts: never miss a scheduled service, photo proof for every visit. | O6: /demo?industry=facilities&client=Kleenol%20Nigeria%20Limited | P6: https://www.kleenolng.com/ | Q6: Not contacted
A7: A | B7: Kresta Laurel Limited | C7: Facility management | D7: Lifts & escalators | E7: Nigeria | F7: Lagos | G7: kresta@krestalaurel.com | H7: Company inbox | I7: 08037959341 | J7: https://krestalaurel.com/ | K7: https://www.linkedin.com/company/kresta-laurel-limited/ | L7: Elevators, escalators, generators, UPS and engineering services, with branches in Lagos, Abuja, Port Harcourt, Ibadan and Uyo. | M7: Lifts, generators and UPS with five branches. | N7: Entrapment callouts and statutory inspections: response-time SLAs and inspection records per lift. | O7: /demo?industry=facilities&client=Kresta%20Laurel%20Limited | P7: https://krestalaurel.com/ | Q7: Not contacted
A8: A | B8: Lift Elevator Craft | C8: Facility management | D8: Lifts & escalators | E8: Nigeria | F8: Lagos | G8: info@liftelevator.com.ng | H8: Company inbox | I8: +234 802 751 8309 | J8: https://www.liftelevator.com.ng/ | L8: Elevator repair, maintenance and installation for commercial and residential buildings in Lagos, Abuja and Anambra. | M8: Core fit: recurring field maintenance across many sites. Multi-location. | N8: Entrapment callouts and statutory inspections: response-time SLAs and inspection records per lift. | O8: /demo?industry=facilities&client=Lift%20Elevator%20Craft | P8: https://www.liftelevator.com.ng/ | Q8: Not contacted
A9: A | B9: Orakl Solutions | C9: Facility management | D9: Lifts & escalators | E9: Nigeria | F9: Lagos | G9: hello@orakl-solutions.com | H9: Company inbox | I9: +234 913 333 3989 | J9: https://orakl-solutions.com/ | K9: https://www.linkedin.com/company/orakl-solutions/ | L9: Elevator and escalator installation and maintenance, with offices in Lagos, Abuja and Port Harcourt. | M9: Core fit: recurring field maintenance across many sites. Multi-location. | N9: Entrapment callouts and statutory inspections: response-time SLAs and inspection records per lift. | O9: /demo?industry=facilities&client=Orakl%20Solutions | P9: https://orakl-solutions.com/ | Q9: Not contacted
A10: A | B10: Sarakeys | C10: Facility management | D10: Lifts & escalators | E10: Nigeria | F10: Ota | G10: info@sarakeys.com.ng | H10: Company inbox | I10: +234 909 971 7070 | J10: http://www.sarakeys.com.ng/ | L10: Elevator and escalator sales, installation and servicing for commercial and residential buildings. | M10: Core fit: recurring field maintenance across many sites. | N10: Entrapment callouts and statutory inspections: response-time SLAs and inspection records per lift. | O10: /demo?industry=facilities&client=Sarakeys | P10: http://www.sarakeys.com.ng/ | Q10: Not contacted
A11: A | B11: Solid Rock Facility Managers | C11: Facility management | D11: Integrated FM | E11: Nigeria | F11: Lagos | G11: info@solidrockfacilitymanagers.com | H11: Company inbox | I11: +234 706 448 7048 | J11: http://solidrockfacilitymanagers.com/ | L11: Maintenance and facility management services since 2008, with offices in Lagos, Port Harcourt, Abuja and Ilorin. | M11: Core fit: recurring field maintenance across many sites. Multi-location. | N11: Multi-building portfolio: planned maintenance schedules, technician dispatch and per-building client reporting. | O11: /demo?industry=facilities&client=Solid%20Rock%20Facility%20Managers | P11: http://solidrockfacilitymanagers.com/ | Q11: Not contacted
A12: A | B12: Tecnicool Nigeria Limited | C12: Facility management | D12: HVAC maintenance | E12: Nigeria | F12: Lagos | G12: info@tecnicoolnig.com | H12: Company inbox | I12: 08098899935 | J12: https://tecnicoolnig.com/ | L12: Commercial HVAC sales, installation and maintenance with offices in Lagos, Abuja, Ilorin and Kaduna. | M12: Good fit: maintenance work across client sites. Multi-location. | N12: Annual maintenance contracts: never miss a scheduled service, photo proof for every visit. | O12: /demo?industry=facilities&client=Tecnicool%20Nigeria%20Limited | P12: https://tecnicoolnig.com/ | Q12: Not contacted
A13: A | B13: Ashipa Electric Limited | C13: Solar | D13: Mini-grid developer/operator | E13: Nigeria | F13: Abuja | G13: info@ashipaelectric.com | H13: Company inbox | J13: https://www.ashipaelectric.com | K13: https://www.linkedin.com/company/ashipaelectric/ | L13: Solar, storage, microgrid and EPC services in West Africa and North America; West Africa office in Garki, Abuja | M13: Core fit: recurring field maintenance across many sites. | N13: Many remote sites and funder/lender reporting (DARES, AMDA etc.): GPS-verified O&M visits and photo evidence financiers trust. | O13: /demo?industry=solar&client=Ashipa%20Electric%20Limited | P13: https://www.ashipaelectric.com | Q13: Not contacted
A14: A | B14: DB Energy | C14: Solar | D14: C&I solar / EPC | E14: Nigeria | F14: Asaba | G14: info@dbenergy.com.ng | H14: Company inbox | I14: +234 706 514 9178 | J14: https://www.dbenergy.ng | K14: https://linkedin.com/company/dbenergy | L14: Residential and C&I solar installation and maintenance (5MW installed) in Lagos, Abuja, Port Harcourt, Enugu, Benin and Asaba | M14: Good fit: maintenance work across client sites. Multi-location. | N14: Turn one-off installs into recurring maintenance contracts: scheduled PM per site and client-facing service reports. | O14: /demo?industry=solar&client=DB%20Energy | P14: https://www.dbenergy.ng | Q14: Not contacted
A15: A | B15: Darway Coast Ltd | C15: Solar | D15: Mini-grid developer/operator | E15: Nigeria | F15: Abuja | G15: support@darwaycoast.com | H15: Company inbox | I15: 0803 3889 202 | J15: https://darwaycoast.com | K15: https://www.linkedin.com/company/darway-coast-ltd | L15: Mini-grid developer with 30+ solar mini-grids (~3.5MW) across 8 states and offices in Abuja, Lagos and Owerri; DARES grantee | M15: Core fit: recurring field maintenance across many sites. Multi-location. | N15: Many remote sites and funder/lender reporting (DARES, AMDA etc.): GPS-verified O&M visits and photo evidence financiers trust. | O15: /demo?industry=solar&client=Darway%20Coast%20Ltd | P15: https://darwaycoast.com | Q15: Not contacted
A16: A | B16: EM-ONE Energy Solutions | C16: Solar | D16: Mini-grid developer/operator | E16: Nigeria | F16: Abuja | G16: info@emone.energy | H16: Company inbox | J16: https://www.emone.energy | K16: https://ca.linkedin.com/company/em-one-energy | L16: Solar microgrid EPC (3.1MW University of Abuja, 1MW Kano interconnected mini-grid); global HQ in Abuja | M16: Core fit: recurring field maintenance across many sites. | N16: Many remote sites and funder/lender reporting (DARES, AMDA etc.): GPS-verified O&M visits and photo evidence financiers trust. | O16: /demo?industry=solar&client=EM-ONE%20Energy%20Solutions | P16: https://www.emone.energy | Q16: Not contacted
A17: A | B17: EtinPower Limited | C17: Solar | D17: Mini-grid developer/operator | E17: Nigeria | F17: Benin City | G17: info@etinpower.com | H17: Company inbox | I17: +234 903 175 1422 | J17: https://www.etinpower.com | K17: https://linkedin.com/company/etinpowerlimited | L17: Solar mini-grid developer and operator for off-grid communities (e.g. Gbelebu, Edo State); AMDA member | M17: Core fit: recurring field maintenance across many sites. | N17: Many remote sites and funder/lender reporting (DARES, AMDA etc.): GPS-verified O&M visits and photo evidence financiers trust. | O17: /demo?industry=solar&client=EtinPower%20Limited | P17: https://www.etinpower.com | Q17: Not contacted
A18: A | B18: Greenage Technologies Power Systems | C18: Solar | D18: Mini-grid developer/operator | E18: Nigeria | F18: Enugu | G18: contact@greenagetech.com | H18: Company inbox | J18: https://greenagetech.com | K18: https://ng.linkedin.com/company/greenage-technologies | L18: Mini-grids, solar installation and engineering, plus its own inverter line (3.5-20KVA) | M18: Core fit: recurring field maintenance across many sites. | N18: Many remote sites and funder/lender reporting (DARES, AMDA etc.): GPS-verified O&M visits and photo evidence financiers trust. | O18: /demo?industry=solar&client=Greenage%20Technologies%20Power%20Systems | P18: https://greenagetech.com/contact-us/ | Q18: Not contacted
A19: A | B19: Havenhill Synergy Ltd | C19: Solar | D19: Mini-grid developer/operator | E19: Nigeria | F19: Abuja | G19: info@havenhillsynergy.com | H19: Company inbox | I19: +2347063803881 | J19: https://havenhillsynergy.com | K19: https://www.linkedin.com/company/havenhill-synergy/ | L19: Clean-tech utility running rural solar mini-grids plus commercial and healthcare solar electrification; received IMAS mini-grid grants | M19: Core fit: recurring field maintenance across many sites. | N19: Many remote sites and funder/lender reporting (DARES, AMDA etc.): GPS-verified O&M visits and photo evidence financiers trust. | O19: /demo?industry=solar&client=Havenhill%20Synergy%20Ltd | P19: https://havenhillsynergy.com | Q19: Not contacted
A20: A | B20: Indicel Solar | C20: Solar | D20: C&I solar / EPC | E20: Nigeria | F20: Enugu | G20: info@indicelsolar.com | H20: Company inbox | I20: +2348108497593 | J20: https://indicelsolar.com | L20: Residential, hybrid and large-scale solar installation and servicing since 2009; offices in Enugu, Abuja and Asaba | M20: Good fit: maintenance work across client sites. Multi-location. | N20: Turn one-off installs into recurring maintenance contracts: scheduled PM per site and client-facing service reports. | O20: /demo?industry=solar&client=Indicel%20Solar | P20: https://indicelsolar.com/contact.php | Q20: Not contacted
A21: A | B21: Prado Power | C21: Solar | D21: Mini-grid developer/operator | E21: Nigeria | F21: Abuja | G21: info@pradopower.org | H21: Company inbox | I21: +234 808 220 9245 | J21: https://www.pradopower.org | K21: https://www.linkedin.com/company/11107148 | L21: Microgrids, solar installations and energy management for off-grid and underserved communities | M21: Core fit: recurring field maintenance across many sites. | N21: Many remote sites and funder/lender reporting (DARES, AMDA etc.): GPS-verified O&M visits and photo evidence financiers trust. | O21: /demo?industry=solar&client=Prado%20Power | P21: https://www.pradopower.org | Q21: Not contacted
A22: A | B22: PriVida Power Limited | C22: Solar | D22: Mini-grid developer/operator | E22: Nigeria | F22: Lagos | G22: info@prividaenergy.com | H22: Company inbox | I22: +441919085632 | J22: https://www.prividaenergy.com | K22: https://www.linkedin.com/company/privida-energy | L22: Mini-grid developer (DARES/NEP grantee, rolling out in 25 communities); Lagos office plus UK office | M22: Core fit: recurring field maintenance across many sites. | N22: Many remote sites and funder/lender reporting (DARES, AMDA etc.): GPS-verified O&M visits and photo evidence financiers trust. | O22: /demo?industry=solar&client=PriVida%20Power%20Limited | P22: https://www.prividaenergy.com | Q22: Not contacted
A23: A | B23: Protergia Energy Nigeria | C23: Solar | D23: Mini-grid developer/operator | E23: Nigeria | F23: Abuja | G23: info@protergiaenergy.com | H23: Company inbox | I23: +234 806 998 3828 | J23: https://protergiaenergy.com | K23: https://www.linkedin.com/company/protergiaenergy/ | L23: Clean-energy utility and mini-grid developer for underserved communities; DARES mini-grid grantee | M23: Core fit: recurring field maintenance across many sites. | N23: Many remote sites and funder/lender reporting (DARES, AMDA etc.): GPS-verified O&M visits and photo evidence financiers trust. | O23: /demo?industry=solar&client=Protergia%20Energy%20Nigeria | P23: https://protergiaenergy.com | Q23: Not contacted
A24: A | B24: Rubitec Solar | C24: Solar | D24: Mini-grid developer/operator | E24: Nigeria | F24: Lagos | G24: info@rubitecsolar.com | H24: Company inbox | I24: +2347087054296 | J24: https://rubitecsolar.com | L24: Installs and maintains solar, inverter backup and small hydro/biomass systems, and develops mini-grid electrification projects; IMAS grantee | M24: Core fit: recurring field maintenance across many sites. | N24: Many remote sites and funder/lender reporting (DARES, AMDA etc.): GPS-verified O&M visits and photo evidence financiers trust. | O24: /demo?industry=solar&client=Rubitec%20Solar | P24: https://rubitecsolar.com | Q24: Not contacted
A25: A | B25: Solarlify | C25: Solar | D25: Residential & small commercial installer | E25: Nigeria | F25: Lagos | G25: admin@solarlify.com.ng | H25: Company inbox | I25: 090-240-224-84 | J25: https://solarlify.com.ng | L25: Solar and inverter installation, repair and maintenance; 1,275+ customers and 20+ branches across 7 states | M25: 20+ branches and a service/repair business: dispatch pain. | N25: High volume of service calls across many homes: dispatch the nearest technician and track repeat faults. | O25: /demo?industry=solar&client=Solarlify | P25: https://solarlify.com.ng | Q25: Not contacted
A26: A | B26: Sosai Renewable Energies Company | C26: Solar | D26: Mini-grid developer/operator | E26: Nigeria | F26: Kaduna | G26: sosai@sosairen.org | H26: Company inbox | I26: +234 809 230 5719 | J26: https://sosairen.org | K26: https://www.linkedin.com/company/sosai-renewable-energies-company/ | L26: Mini-grid and household solar developer with offices in Kaduna and Abuja; IMAS grantee | M26: Core fit: recurring field maintenance across many sites. Multi-location. | N26: Many remote sites and funder/lender reporting (DARES, AMDA etc.): GPS-verified O&M visits and photo evidence financiers trust. | O26: /demo?industry=solar&client=Sosai%20Renewable%20Energies%20Company | P26: https://sosairen.org/contact-us/ | Q26: Not contacted
A27: A | B27: Sunhive Limited | C27: Solar | D27: Mini-grid developer/operator | E27: Nigeria | F27: Lagos | G27: info@sunhive.com | H27: Company inbox | I27: +234 806 456 5176 | J27: https://sunhive.com | K27: https://www.linkedin.com/company/sunhive-ltd/ | L27: Solar EPC with 10MWp+ delivered, plus mini-grids and battery storage; hubs in Lagos and Kano | M27: Core fit: recurring field maintenance across many sites. | N27: Many remote sites and funder/lender reporting (DARES, AMDA etc.): GPS-verified O&M visits and photo evidence financiers trust. | O27: /demo?industry=solar&client=Sunhive%20Limited | P27: https://sunhive.com | Q27: Not contacted
A28: A | B28: CETECH Ghana | C28: Facility management | D28: HVAC maintenance | E28: Ghana | G28: support@cetechbpa.com | H28: Company inbox | I28: +233539003030 | J28: https://cetechbpa.com/ | L28: HVAC/R design, installation, maintenance and repair for residential, commercial and industrial clients across Ghana. | M28: Good fit: maintenance work across client sites. Multi-location. | N28: Annual maintenance contracts: never miss a scheduled service, photo proof for every visit. | O28: /demo?industry=facilities&client=CETECH%20Ghana | P28: https://cetechbpa.com/gh/contact-us/ | Q28: Not contacted
A29: A | B29: Diamond Maintenance Tanzania Limited | C29: Facility management | D29: Integrated FM | E29: Tanzania | F29: Dar es Salaam | G29: info@dm.co.tz | H29: Company inbox | I29: +255 745 406484 | J29: https://dm.co.tz/ | K29: https://www.linkedin.com/company/dmtl-africa | L29: Integrated FM company providing property maintenance, technical services, renovation and sanitation across Tanzania. | M29: Core fit: recurring field maintenance across many sites. Multi-location. | N29: Multi-building portfolio: planned maintenance schedules, technician dispatch and per-building client reporting. | O29: /demo?industry=facilities&client=Diamond%20Maintenance%20Tanzania%20Limited | P29: https://dm.co.tz/ | Q29: Not contacted
A30: A | B30: Elevator Maintenance Company (EMC) | C30: Facility management | D30: Lifts & escalators | E30: South Africa | F30: Pretoria | G30: sales@elevatorcompany.co.za | H30: Company inbox | I30: 012 377 0606 | J30: https://elevatorcompany.co.za/ | K30: https://www.linkedin.com/company/elevator-maintenance-company/ | L30: Multi-brand lift and elevator maintenance, repair, installation and modernisation across South Africa. | M30: Core fit: recurring field maintenance across many sites. Multi-location. | N30: Entrapment callouts and statutory inspections: response-time SLAs and inspection records per lift. | O30: /demo?industry=facilities&client=Elevator%20Maintenance%20Company | P30: https://elevatorcompany.co.za/ | Q30: Not contacted
A31: A | B31: Facilities Management Solutions (FM Solutions) | C31: Facility management | D31: Integrated FM | E31: South Africa | F31: Cape Town | G31: info@fm-solutions.co.za | H31: Company inbox | I31: 086 002 2175 | J31: https://www.fm-solutions.co.za/ | K31: https://www.linkedin.com/company/afroteq-fm-solutions | L31: Integrated technical and soft-services FM provider (part of AFMS Group) doing preventive, corrective and emergency repairs, with offices in Cape Town, Midrand, eThekwini, Gqeberha and Gaborone. | M31: Multi-office technical FM with emergency repairs. | N31: Multi-building portfolio: planned maintenance schedules, technician dispatch and per-building client reporting. | O31: /demo?industry=facilities&client=Facilities%20Management%20Solutions | P31: https://www.fm-solutions.co.za/ | Q31: Not contacted
A32: A | B32: Gamma Heights Engineering | C32: Facility management | D32: Lifts & escalators | E32: Ghana | F32: Accra | G32: sales@gammaheightseng.com | H32: Company inbox | I32: +233 24 438 8165 | J32: https://gammaheightseng.com/ | L32: Supply, installation and maintenance of elevators, escalators, moving walkways and dumbwaiters. | M32: Core fit: recurring field maintenance across many sites. | N32: Entrapment callouts and statutory inspections: response-time SLAs and inspection records per lift. | O32: /demo?industry=facilities&client=Gamma%20Heights%20Engineering | P32: https://gammaheightseng.com/Contact | Q32: Not contacted
A33: A | B33: LeafySpace (Pty) Ltd | C33: Facility management | D33: Integrated FM | E33: South Africa | F33: Kempton Park | G33: info@leafyspace.co.za | H33: Company inbox | I33: +27 11 028 7635 | J33: https://leafyspace.co.za/ | K33: https://www.linkedin.com/company/leafyspace/ | L33: Facilities management provider covering building management, maintenance, electrical, plumbing and cleaning across South Africa. | M33: Core fit: recurring field maintenance across many sites. Multi-location. | N33: Multi-building portfolio: planned maintenance schedules, technician dispatch and per-building client reporting. | O33: /demo?industry=facilities&client=LeafySpace | P33: https://leafyspace.co.za/ | Q33: Not contacted
A34: A | B34: M-Cool Electro Engineering Services Limited | C34: Facility management | D34: HVAC maintenance | E34: Kenya | F34: Nairobi | G34: mcoolelectroengineeringlimited@gmail.com | H34: Free-mail inbox | I34: +254 723 428 167 | J34: https://mcool.co.ke/ | L34: Commercial HVAC, air conditioning, cold room, refrigeration and mechanical ventilation installation and maintenance across Kenya. | M34: Good fit: maintenance work across client sites. Multi-location. | N34: Annual maintenance contracts: never miss a scheduled service, photo proof for every visit. | O34: /demo?industry=facilities&client=M-Cool%20Electro%20Engineering%20Services%20Limited | P34: https://mcool.co.ke/ | Q34: Not contacted
A35: A | B35: Musandah Assets Management | C35: Facility management | D35: Integrated FM | E35: Egypt | G35: info@musandahfm.com | H35: Company inbox | J35: https://musandahfm.com/ | K35: https://www.linkedin.com/company/musandahassetsandfm/ | L35: Egyptian integrated FM provider focused on MEP maintenance and asset management nationwide. | M35: Core fit: recurring field maintenance across many sites. Multi-location. | N35: Multi-building portfolio: planned maintenance schedules, technician dispatch and per-building client reporting. | O35: /demo?industry=facilities&client=Musandah%20Assets%20Management | P35: https://musandahfm.com/contact/ | Q35: Not contacted
A36: A | B36: PKBA Engineering Co | C36: Facility management | D36: HVAC maintenance | E36: Ghana | F36: Accra | G36: info@pkbaengineeringco.com | H36: Company inbox | I36: +233 261609308 | J36: https://pkbaengineeringco.com/ | L36: Air conditioning installation and repair, ventilation, electrical and plumbing services across Ghana. | M36: Good fit: maintenance work across client sites. Multi-location. | N36: Annual maintenance contracts: never miss a scheduled service, photo proof for every visit. | O36: /demo?industry=facilities&client=PKBA%20Engineering%20Co | P36: https://pkbaengineeringco.com/ | Q36: Not contacted
A37: A | B37: Relis Lifts | C37: Facility management | D37: Lifts & escalators | E37: South Africa | F37: Midrand | G37: info@relislifts.co.za | H37: Company inbox | I37: +27 11 733 4033 | J37: https://relislifts.co.za/ | L37: Lift and escalator company doing installation, maintenance, repair, modernisation and 24-hour emergency callouts across South Africa. | M37: Core fit: recurring field maintenance across many sites. Multi-location. | N37: Entrapment callouts and statutory inspections: response-time SLAs and inspection records per lift. | O37: /demo?industry=facilities&client=Relis%20Lifts | P37: https://relislifts.co.za/ | Q37: Not contacted
A38: A | B38: Rise Elevators | C38: Facility management | D38: Lifts & escalators | E38: South Africa | G38: sales@riseelevators.co.za | H38: Company inbox | I38: +27 839 381 676 | J38: https://www.riseelevators.co.za/ | L38: Lift and escalator installation, maintenance, repairs, modernisation and safety inspections, with committed emergency response times. | M38: Core fit: recurring field maintenance across many sites. | N38: Entrapment callouts and statutory inspections: response-time SLAs and inspection records per lift. | O38: /demo?industry=facilities&client=Rise%20Elevators | P38: https://www.riseelevators.co.za/contact | Q38: Not contacted
A39: A | B39: SPINX (SPXSA) | C39: Facility management | D39: Property / estate FM | E39: South Africa | F39: Cape Town | G39: fs@spxsa.com | H39: Company inbox | I39: 087 550 0942 | J39: https://spxsa.com/ | L39: National commercial property maintenance firm with 24/7 response, planned maintenance, refurbishments and technical projects across Cape Town, Johannesburg, Pretoria, Durban, Gqeberha and East London. | M39: National 24/7 maintenance across six cities: core fit. | N39: Tenant requests become tracked work orders with technician dispatch and landlord reporting. | O39: /demo?industry=facilities&client=SPINX | P39: https://spxsa.com/ | Q39: Not contacted
A40: A | B40: ARC Power Ltd | C40: Solar | D40: Mini-grid developer/operator | E40: Rwanda | G40: info@arcpower.co | H40: Company inbox | I40: +250 787 372 047 | J40: https://arcpower.co/ | K40: https://www.linkedin.com/company/arc-power-rw/ | L40: Solar mini-grid developer and operator with offices in Rwanda, Zambia and Mozambique. | M40: Core fit: recurring field maintenance across many sites. Multi-location. | N40: Many remote sites and funder/lender reporting (DARES, AMDA etc.): GPS-verified O&M visits and photo evidence financiers trust. | O40: /demo?industry=solar&client=ARC%20Power%20Ltd | P40: https://arcpower.co/ | Q40: Not contacted
...

Sheet Summary
A1: Lead list summary
A2: All counts are live formulas over the Leads tab.
A4: Country | B4: Solar | C4: Facility mgmt | D4: Total | E4: With email | F4: Priority A
A5: Nigeria | B5: =COUNTIFS(Leads!$E$2:$E$161,$A5,Leads!$C$2:$C$161,"Solar") -> 40 | C5: =COUNTIFS(Leads!$E$2:$E$161,$A5,Leads!$C$2:$C$161,"Facility management") -> 40 | D5: =B5+C5 -> 80 | E5: =COUNTIFS(Leads!$E$2:$E$161,$A5,Leads!$G$2:$G$161,"<>") -> 67 | F5: =COUNTIFS(Leads!$E$2:$E$161,$A5,Leads!$A$2:$A$161,"A") -> 32
A6: Egypt | B6: =COUNTIFS(Leads!$E$2:$E$161,$A6,Leads!$C$2:$C$161,"Solar") -> 0 | C6: =COUNTIFS(Leads!$E$2:$E$161,$A6,Leads!$C$2:$C$161,"Facility management") -> 7 | D6: =B6+C6 -> 7 | E6: =COUNTIFS(Leads!$E$2:$E$161,$A6,Leads!$G$2:$G$161,"<>") -> 6 | F6: =COUNTIFS(Leads!$E$2:$E$161,$A6,Leads!$A$2:$A$161,"A") -> 1
A7: Ghana | B7: =COUNTIFS(Leads!$E$2:$E$161,$A7,Leads!$C$2:$C$161,"Solar") -> 6 | C7: =COUNTIFS(Leads!$E$2:$E$161,$A7,Leads!$C$2:$C$161,"Facility management") -> 9 | D7: =B7+C7 -> 15 | E7: =COUNTIFS(Leads!$E$2:$E$161,$A7,Leads!$G$2:$G$161,"<>") -> 14 | F7: =COUNTIFS(Leads!$E$2:$E$161,$A7,Leads!$A$2:$A$161,"A") -> 4
A8: Kenya | B8: =COUNTIFS(Leads!$E$2:$E$161,$A8,Leads!$C$2:$C$161,"Solar") -> 10 | C8: =COUNTIFS(Leads!$E$2:$E$161,$A8,Leads!$C$2:$C$161,"Facility management") -> 8 | D8: =B8+C8 -> 18 | E8: =COUNTIFS(Leads!$E$2:$E$161,$A8,Leads!$G$2:$G$161,"<>") -> 18 | F8: =COUNTIFS(Leads!$E$2:$E$161,$A8,Leads!$A$2:$A$161,"A") -> 5
A9: Morocco | B9: =COUNTIFS(Leads!$E$2:$E$161,$A9,Leads!$C$2:$C$161,"Solar") -> 0 | C9: =COUNTIFS(Leads!$E$2:$E$161,$A9,Leads!$C$2:$C$161,"Facility management") -> 2 | D9: =B9+C9 -> 2 | E9: =COUNTIFS(Leads!$E$2:$E$161,$A9,Leads!$G$2:$G$161,"<>") -> 1 | F9: =COUNTIFS(Leads!$E$2:$E$161,$A9,Leads!$A$2:$A$161,"A") -> 0
A10: Rwanda | B10: =COUNTIFS(Leads!$E$2:$E$161,$A10,Leads!$C$2:$C$161,"Solar") -> 2 | C10: =COUNTIFS(Leads!$E$2:$E$161,$A10,Leads!$C$2:$C$161,"Facility management") -> 3 | D10: =B10+C10 -> 5 | E10: =COUNTIFS(Leads!$E$2:$E$161,$A10,Leads!$G$2:$G$161,"<>") -> 3 | F10: =COUNTIFS(Leads!$E$2:$E$161,$A10,Leads!$A$2:$A$161,"A") -> 2
A11: South Africa | B11: =COUNTIFS(Leads!$E$2:$E$161,$A11,Leads!$C$2:$C$161,"Solar") -> 14 | C11: =COUNTIFS(Leads!$E$2:$E$161,$A11,Leads!$C$2:$C$161,"Facility management") -> 8 | D11: =B11+C11 -> 22 | E11: =COUNTIFS(Leads!$E$2:$E$161,$A11,Leads!$G$2:$G$161,"<>") -> 20 | F11: =COUNTIFS(Leads!$E$2:$E$161,$A11,Leads!$A$2:$A$161,"A") -> 11
A12: Tanzania | B12: =COUNTIFS(Leads!$E$2:$E$161,$A12,Leads!$C$2:$C$161,"Solar") -> 4 | C12: =COUNTIFS(Leads!$E$2:$E$161,$A12,Leads!$C$2:$C$161,"Facility management") -> 2 | D12: =B12+C12 -> 6 | E12: =COUNTIFS(Leads!$E$2:$E$161,$A12,Leads!$G$2:$G$161,"<>") -> 6 | F12: =COUNTIFS(Leads!$E$2:$E$161,$A12,Leads!$A$2:$A$161,"A") -> 4
A13: Uganda | B13: =COUNTIFS(Leads!$E$2:$E$161,$A13,Leads!$C$2:$C$161,"Solar") -> 2 | C13: =COUNTIFS(Leads!$E$2:$E$161,$A13,Leads!$C$2:$C$161,"Facility management") -> 1 | D13: =B13+C13 -> 3 | E13: =COUNTIFS(Leads!$E$2:$E$161,$A13,Leads!$G$2:$G$161,"<>") -> 2 | F13: =COUNTIFS(Leads!$E$2:$E$161,$A13,Leads!$A$2:$A$161,"A") -> 0
A14: Zambia | B14: =COUNTIFS(Leads!$E$2:$E$161,$A14,Leads!$C$2:$C$161,"Solar") -> 2 | C14: =COUNTIFS(Leads!$E$2:$E$161,$A14,Leads!$C$2:$C$161,"Facility management") -> 0 | D14: =B14+C14 -> 2 | E14: =COUNTIFS(Leads!$E$2:$E$161,$A14,Leads!$G$2:$G$161,"<>") -> 1 | F14: =COUNTIFS(Leads!$E$2:$E$161,$A14,Leads!$A$2:$A$161,"A") -> 2
A15: Total | B15: =SUM(B5:B14) -> 80 | C15: =SUM(C5:C14) -> 80 | D15: =SUM(D5:D14) -> 160 | E15: =SUM(E5:E14) -> 138 | F15: =SUM(F5:F14) -> 61
A17: Priority | B17: Leads | C17: With email | D17: Meaning
A18: A | B18: =COUNTIF(Leads!$A$2:$A$161,A18) -> 61 | C18: =COUNTIFS(Leads!$A$2:$A$161,A18,Leads!$G$2:$G$161,"<>") -> 53 | D18: Core fit: recurring field maintenance across many sites. Start here.
A19: B | B19: =COUNTIF(Leads!$A$2:$A$161,A19) -> 79 | C19: =COUNTIFS(Leads!$A$2:$A$161,A19,Leads!$G$2:$G$161,"<>") -> 69 | D19: Good fit; qualify on a call.
A20: C | B20: =COUNTIF(Leads!$A$2:$A$161,A20) -> 20 | C20: =COUNTIFS(Leads!$A$2:$A$161,A20,Leads!$G$2:$G$161,"<>") -> 16 | D20: Weaker fit (very large, in-house tech, or mostly product sales).
A22: Outreach status | B22: Count
A23: Not contacted | B23: =COUNTIF(Leads!$Q$2:$Q$161,A23) -> 160
A24: Sent | B24: =COUNTIF(Leads!$Q$2:$Q$161,A24) -> 0
A25: Follow-up 1 sent | B25: =COUNTIF(Leads!$Q$2:$Q$161,A25) -> 0
A26: Follow-up 2 sent | B26: =COUNTIF(Leads!$Q$2:$Q$161,A26) -> 0
A27: Replied | B27: =COUNTIF(Leads!$Q$2:$Q$161,A27) -> 0
A28: Meeting booked | B28: =COUNTIF(Leads!$Q$2:$Q$161,A28) -> 0
A29: Not interested | B29: =COUNTIF(Leads!$Q$2:$Q$161,A29) -> 0
A30: Bounced | B30: =COUNTIF(Leads!$Q$2:$Q$161,A30) -> 0

Sheet Email templates
A1: Cold email templates
A2: Replace {{Company}}, {{FirstName}} and {{DemoLink}} (your demo URL + the row's demo link path). Keep it plain text, one link, no attachments.
A4: Segment | B4: Step | C4: Subject / body
A5: Solar & mini-grids | B5: Email 1 (day 0) | C5: Subject: {{Company}}'s field team Hi {{FirstName}}, When a company runs installations or mini-grids across many sites, maintenance usually lives in WhatsApp groups and spreadsheets. Then a client, lender or funder asks for proof of O&M and someone spends a week pulling it together. We build custom field-operations software for energy companies: jobs sent to technicians' phones, GPS-verified site check-ins, time-stamped photo inspections, and a live view of every asset. I set up a short demo with {{Company}}'s name on it. It shows a technician reporting an inverter fault and the ops team dispatching a fix: {{DemoLink}} Would a 20-minute call to see if it fits how your team works be useful? Perfection Loveday Opensaucery
A6: Solar & mini-grids | B6: Follow-up 1 (day 3–4) | C6: Subject: Re: {{Company}}'s field team Hi {{FirstName}}, one detail that tends to matter to operators: every site visit is logged with GPS and photos taken in the app, so you can show exactly when each asset was last serviced, and what was found, without chasing anyone. The demo is here if you'd like a look: {{DemoLink}} Perfection
A7: Solar & mini-grids | B7: Follow-up 2 (day 8–10) | C7: Subject: Close the loop? Hi {{FirstName}}, I'll stop here so I'm not cluttering your inbox. If tracking maintenance across your sites becomes a priority later, just reply to this email and I'll send over a version built around your actual sites and equipment. Perfection
A8: Facility management | B8: Email 1 (day 0) | C8: Subject: Maintenance across {{Company}}'s buildings Hi {{FirstName}}, FM teams running chillers, lifts, generators and PPM schedules across many buildings often juggle job cards, calls and spreadsheets. Then a client asks for proof that a visit happened. We build custom maintenance and field-operations software: work orders sent to engineers' phones, GPS-verified check-ins, photo-stamped checklists, planned maintenance schedules and a live dashboard per building. I set up a short demo with {{Company}}'s name on it. It shows a chiller trip being reported and an engineer dispatched in under a minute: {{DemoLink}} Would a 20-minute call be worth it to see if it fits how you work? Perfection Loveday Opensaucery
A9: Facility management | B9: Follow-up 1 (day 3–4) | C9: Subject: Re: Maintenance across {{Company}}'s buildings Hi {{FirstName}}, one thing FM clients tend to value: every visit comes with GPS proof and photos, and the client report writes itself at month-end. No more rebuilding it from job cards. Demo: {{DemoLink}} Perfection
A10: Facility management | B10: Follow-up 2 (day 8–10) | C10: Subject: Close the loop? Hi {{FirstName}}, I'll leave it here. If digitising maintenance across your portfolio comes up later, reply and I'll put together a version using your buildings and equipment. Perfection

Sheet How this was built
A1: How this list was built
A2: • Companies found by web research (industry lists, association and funder programme lists like DARES/IMAS/AMDA, and company websites) on 22 Sept 2026.
A3: • Every email and phone was read from the company's own website or a public listing. Nothing was guessed or generated. The source is in the 'Email source' column.
A4: • Apify was not used: the account did not have enough credit this billing cycle.
A6: Before you send
A7: • Emails were NOT verified with a mail-server check. Run the list through a verifier (e.g. NeverBounce, ZeroBounce, or Apify email verification once topped up) to avoid bounces hurting your domain.
A8: • Most addresses are company inboxes (info@, sales@). Where you can, find the operations or maintenance lead on LinkedIn and address them by name.
A9: • Send from a secondary domain (e.g. opensaucery-mail.com) warmed up for 2–3 weeks, 20–30 emails/day to start.
A10: • Include who you are, a real postal address and a one-line opt-out. Honour opt-outs. Nigeria (NDPA), Kenya (Data Protection Act), South Africa (POPIA) and Ghana all have data-protection rules on marketing; B2B cold email to company inboxes is generally low-risk if you stay honest and let people opt out. This is not legal advice.
A12: Demo links
A13: • The 'Demo link path' column opens the FieldOps demo pre-branded with the company's name. Deploy the dashboard, then prefix each path with your URL, e.g. https://demo.opensaucery.africa/demo?industry=solar&client=Havenhill%20Synergy.
